{"name": "test_mul_exception[a-2]", "status": "passed", "parameters": [{"name": "a", "value": "'a'"}, {"name": "b", "value": "'2'"}], "start": 1604071667228, "stop": 1604071667229, "uuid": "12c83b85-6718-4e97-91bd-1d81e9838665", "historyId": "7914a918c5e7dfef4343cfdb6737985d", "testCaseId": "6b0580f198bea6dfde3f2c578cd856f1", "fullName": "test_calc.TestCalc#test_mul_exception", "labels": [{"name": "suite", "value": "test_calc"}, {"name": "subSuite", "value": "TestCalc"}, {"name": "host", "value": "DESKTOP-1KNB727"}, {"name": "thread", "value": "7620-MainThread"}, {"name": "framework", "value": "pytest"}, {"name": "language", "value": "cpython3"}, {"name": "package", "value": "test_calc"}]}